Workbook

Sheet Start Here
A1: Career & Income Recovery Tracker
A3: Plan start date | B3: 46309
A4: (Change B3 and every date in the tracker shifts.)
A6: HOW TO USE
A7: Every day | B7: Open 'Daily Log' and fill today's row. Takes 2 minutes.
A8: Every application | B8: Add a row in 'Applications'. Log follow-up dates when you send them.
A9: Every message sent | B9: Add a row in 'Outreach' (ex-colleagues, agencies, recruiters, brother's referrals, clients).
A10: Every client lead | B10: Add a row in 'Freelance Pipeline'. Record money only when it is actually received.
A11: Every Sunday | B11: Open 'Weekly Scorecard', fill the yellow cells for the week, then answer the review questions.
A12: Money | B12: Fill 'Money' once, update monthly.
A14: COLOUR LEGEND
A15: Yellow cell, blue text | B15: You type here (inputs and manual numbers).
A16: White cells in tables | B16: Also yours to fill. Row 2 in Applications, Outreach and Freelance Pipeline is a grey EXAMPLE and is not counted. Leave it and start your own entries in row 3.
A17: Black text in Scorecard | B17: Formulas. They count from your other sheets automatically. Do not overwrite.
A19: DECISION RULES
A20: After 50 outreach messages, 0 replies | B20: Change the message and the target audience, not the effort.
A21: After 15 applications, 0 interviews | B21: Rework CV, LinkedIn headline and role targeting.
A22: Interviews but no offers | B22: Spend the next week on interview prep only: explain 2 projects, ORM/indexing, Celery/Redis, system design.
A23: Replies but no paid work after 30 days | B23: Cut the price/scope of the first offer and ask for a small paid trial, never unpaid work.
A24: Low-value time over 3 hrs/week | B24: Block those sites, put the time back into outreach.
A25: Day 30 and Day 90 | B25: Review the scorecard totals and decide: continue, adjust, or switch channel.
A27: RULES TO PROTECT YOU
A28: Never | B28: Pay for Connects, courses, 'job' fees or unknown clients' upfront costs. No unpaid test tasks beyond about 1 hour.
A29: Always | B29: Take 50% upfront from new clients, use a written scope, and deliver in milestones.
A30: No guarantees | B30: This tracker measures effort and results. It does not promise a job or income.
A32: LEARNING PROGRAM SHEETS
A33: Learning Dashboard | B33: Start here each day: today's plan day, progress, readiness, interview checkpoints, charts.
A34: 60-Day Plan | B34: Main daily plan: topic, exercise, DSA, design, interview practice, completion criteria, status, confidence.
A35: 30-Day Accelerated | B35: Alternative if you must compress. Covers two plan-days per day at concept depth.
A36: Daily Schedule | B36: Time blocks, 3-hour fallback, low-energy minimum, recovery rules, interview and paid-project rules.
A37: Curriculum | B37: Topic checklist for all 9 modules with priority tier and evidence.
A38: Skill Assessment | B38: Levels 1-5 at baseline, Day 15/30/45/60 with weighted readiness score.
A39: DSA Log | B39: Every problem with 1-3-7-21 day spaced-review dates.
A40: Mock Interviews | B40: Question, your answer, evaluation, missed concepts, improved answer, follow-up task.
A41: Projects & Review | B41: Project milestones and code review checklist.
A42: Weak Areas | B42: Gaps you discover and the fix plan.
A43: Weekly Review | B43: Review every 7th day: learning plus job-search numbers side by side.
A44: Change Log | B44: What changed in this upgrade.

Sheet Learning Dashboard
A1: Learning Dashboard: 60-day backend mastery plan
A3: Learning start date (Day 1) | B3: 46311 | C3: Change this once. Every plan date follows it. (Assumption: Day 1 = 16 Oct 2026.)
A5: Today is plan day | B5: =MAX(0,MIN(60,TODAY()-B3+1)) -> 0
A6: Plan days completed | B6: =COUNTIF('60-Day Plan'!N2:N61,"Completed") -> 0
A7: Plan days in progress | B7: =COUNTIF('60-Day Plan'!N2:N61,"In Progress") -> 0
A8: Plan days blocked | B8: =COUNTIF('60-Day Plan'!N2:N61,"Blocked") -> 0
A9: Percent complete | B9: =B6/60 -> 0
A10: Days behind schedule | B10: =MAX(0,MAX(0,MIN(60,TODAY()-B3))-B6) -> 0
A11: Average confidence (rated days) | B11: =IFERROR(AVERAGE('60-Day Plan'!O2:O61),"")
A12: Curriculum topics completed | B12: =COUNTIF(Curriculum!F2:F139,"Completed")&" of "&COUNTA(Curriculum!C2:C139) -> 0 of 138
A13: DSA problems logged | B13: =COUNTA('DSA Log'!C3:C201) -> 0
A14: Mock interviews logged | B14: =COUNTA('Mock Interviews'!F3:F201) -> 0
A15: Open weak areas | B15: =COUNTIFS('Weak Areas'!D2:D101,"<>",'Weak Areas'!I2:I101,"<>Fixed") -> 0
A16: Weighted readiness score | B16: ='Skill Assessment'!M14 -> 0
A18: Interview checkpoint (mid-level roles) | B18: =IF(OR('Skill Assessment'!J4="",'Skill Assessment'!J5="",'Skill Assessment'!J7="",'Skill Assessment'!J12=""),"Not assessed yet. Complete the baseline on Skill Assessment.",IF(AND('Skill Assessment'!J4>=3,'Skill Assessment'!J5>=3,'Skill Assessment'!J7>=3,'Skill Assessment'!J12>=3),"Ready to accept suitable mid-level interviews. Claim only what you can show.","Keep building. Apply only to roles you clearly match.")) -> Not assessed yet. Complete the baseline on Skill Assessment.
A19: Senior / higher-paying gate | B19: =IF(OR('Skill Assessment'!J4="",'Skill Assessment'!J5="",'Skill Assessment'!J7="",'Skill Assessment'!J10="",'Skill Assessment'!J11=""),"Not assessed yet.",IF(AND('Skill Assessment'!J4>=4,'Skill Assessment'!J5>=4,'Skill Assessment'!J7>=4,'Skill Assessment'!J10>=3,'Skill Assessment'!J11>=3),"Evidence supports senior-level interviews.","Not yet. Close the gaps on Skill Assessment first.")) -> Not assessed yet.
A20: Gate rules (my assumptions, editable in the formulas): mid-level = Python, Django, Databases and Communication at level 3 or more. Senior = Python, Django, Databases at level 4 or more, plus DSA and System Design at level 3 or more.
A22: Phase | B22: Days | C22: Completed | D22: % complete
A23: P1 Foundations | B23: =COUNTIF('60-Day Plan'!C2:C61,A23) -> 10 | C23: =COUNTIFS('60-Day Plan'!C2:C61,A23,'60-Day Plan'!N2:N61,"Completed") -> 0 | D23: =IF(B23=0,0,C23/B23) -> 0
A24: P2 Adv Python, Django & DRF | B24: =COUNTIF('60-Day Plan'!C2:C61,A24) -> 10 | C24: =COUNTIFS('60-Day Plan'!C2:C61,A24,'60-Day Plan'!N2:N61,"Completed") -> 0 | D24: =IF(B24=0,0,C24/B24) -> 0
A25: P3 FastAPI & Backend | B25: =COUNTIF('60-Day Plan'!C2:C61,A25) -> 10 | C25: =COUNTIFS('60-Day Plan'!C2:C61,A25,'60-Day Plan'!N2:N61,"Completed") -> 0 | D25: =IF(B25=0,0,C25/B25) -> 0
A26: P4 Systems & Docker | B26: =COUNTIF('60-Day Plan'!C2:C61,A26) -> 10 | C26: =COUNTIFS('60-Day Plan'!C2:C61,A26,'60-Day Plan'!N2:N61,"Completed") -> 0 | D26: =IF(B26=0,0,C26/B26) -> 0
A27: P5 Cloud & Reliability | B27: =COUNTIF('60-Day Plan'!C2:C61,A27) -> 10 | C27: =COUNTIFS('60-Day Plan'!C2:C61,A27,'60-Day Plan'!N2:N61,"Completed") -> 0 | D27: =IF(B27=0,0,C27/B27) -> 0
A28: P6 Revision & Mocks | B28: =COUNTIF('60-Day Plan'!C2:C61,A28) -> 10 | C28: =COUNTIFS('60-Day Plan'!C2:C61,A28,'60-Day Plan'!N2:N61,"Completed") -> 0 | D28: =IF(B28=0,0,C28/B28) -> 0
A31: Curriculum module | B31: Topics | C31: Completed | D31: % complete | E31: Average level
A32: 1 Python | B32: =COUNTIF(Curriculum!B2:B139,A32) -> 15 | C32: =COUNTIFS(Curriculum!B2:B139,A32,Curriculum!F2:F139,"Completed") -> 0 | D32: =IF(B32=0,0,C32/B32) -> 0 | E32: =IFERROR(AVERAGEIFS(Curriculum!G2:G139,Curriculum!B2:B139,A32),"")
A33: 2 Django & DRF | B33: =COUNTIF(Curriculum!B2:B139,A33) -> 18 | C33: =COUNTIFS(Curriculum!B2:B139,A33,Curriculum!F2:F139,"Completed") -> 0 | D33: =IF(B33=0,0,C33/B33) -> 0 | E33: =IFERROR(AVERAGEIFS(Curriculum!G2:G139,Curriculum!B2:B139,A33),"")
A34: 3 FastAPI | B34: =COUNTIF(Curriculum!B2:B139,A34) -> 11 | C34: =COUNTIFS(Curriculum!B2:B139,A34,Curriculum!F2:F139,"Completed") -> 0 | D34: =IF(B34=0,0,C34/B34) -> 0 | E34: =IFERROR(AVERAGEIFS(Curriculum!G2:G139,Curriculum!B2:B139,A34),"")
A35: 4 Databases & SQL | B35: =COUNTIF(Curriculum!B2:B139,A35) -> 15 | C35: =COUNTIFS(Curriculum!B2:B139,A35,Curriculum!F2:F139,"Completed") -> 0 | D35: =IF(B35=0,0,C35/B35) -> 0 | E35: =IFERROR(AVERAGEIFS(Curriculum!G2:G139,Curriculum!B2:B139,A35),"")
A36: 5 Advanced Backend | B36: =COUNTIF(Curriculum!B2:B139,A36) -> 18 | C36: =COUNTIFS(Curriculum!B2:B139,A36,Curriculum!F2:F139,"Completed") -> 0 | D36: =IF(B36=0,0,C36/B36) -> 0 | E36: =IFERROR(AVERAGEIFS(Curriculum!G2:G139,Curriculum!B2:B139,A36),"")
A37: 6 Docker, Cloud & CI/CD | B37: =COUNTIF(Curriculum!B2:B139,A37) -> 17 | C37: =COUNTIFS(Curriculum!B2:B139,A37,Curriculum!F2:F139,"Completed") -> 0 | D37: =IF(B37=0,0,C37/B37) -> 0 | E37: =IFERROR(AVERAGEIFS(Curriculum!G2:G139,Curriculum!B2:B139,A37),"")
A38: 7 DSA | B38: =COUNTIF(Curriculum!B2:B139,A38) -> 23 | C38: =COUNTIFS(Curriculum!B2:B139,A38,Curriculum!F2:F139,"Completed") -> 0 | D38: =IF(B38=0,0,C38/B38) -> 0 | E38: =IFERROR(AVERAGEIFS(Curriculum!G2:G139,Curriculum!B2:B139,A38),"")
A39: 8 System Design | B39: =COUNTIF(Curriculum!B2:B139,A39) -> 11 | C39: =COUNTIFS(Curriculum!B2:B139,A39,Curriculum!F2:F139,"Completed") -> 0 | D39: =IF(B39=0,0,C39/B39) -> 0 | E39: =IFERROR(AVERAGEIFS(Curriculum!G2:G139,Curriculum!B2:B139,A39),"")
A40: 9 Communication | B40: =COUNTIF(Curriculum!B2:B139,A40) -> 10 | C40: =COUNTIFS(Curriculum!B2:B139,A40,Curriculum!F2:F139,"Completed") -> 0 | D40: =IF(B40=0,0,C40/B40) -> 0 | E40: =IFERROR(AVERAGEIFS(Curriculum!G2:G139,Curriculum!B2:B139,A40),"")

Sheet 60-Day Plan
A1: Day | B1: Date | C1: Phase | D1: Subject | E1: Priority | F1: Core topic | G1: Hands-on exercise | H1: DSA focus | I1: Design / deploy focus | J1: Interview & communication | K1: Est. hrs | L1: Resource | M1: Completion criteria | N1: Status | O1: Confidence (1-5) | P1: Completed on | Q1: Next revision | R1: Assessment result | S1: Weaknesses discovered | T1: Notes / evidence
A2: 1 | B2: ='Learning Dashboard'!$B$3+A2-1 -> 46311 | C2: P1 Foundations | D2: Assessment | E2: Essential | F2: Baseline assessment and environment setup | G2: Rate yourself 1-5 in every subject (Skill Assessment tab, honestly). Set up Python 3.12 venv, git repo, pytest, Postgres in Docker. | H2: 3 easy problems cold, no hints; note time and where you got stuck | I2: - | J2: Write your first 60-90 sec intro draft in your own words and record it | K2: 5 | L2: Skill Assessment + Mock Interviews tabs | M2: Baseline levels entered for all 9 subjects; 3+ weak areas logged; repo and env run tests | N2: Not Started | Q2: =IF(AND(N2="Completed",P2<>""),P2+3,"")
A3: 2 | B3: ='Learning Dashboard'!$B$3+A3-1 -> 46312 | C3: P1 Foundations | D3: Python | E3: Essential | F3: Data types, mutability, comprehensions, functions, *args/**kwargs, scope (LEGB), shallow vs deep copy | G3: Write 10 small functions (default-arg trap, closure counter, copy vs deepcopy); predict output before running | H3: Arrays and strings: 3 easy | I3: - | J3: Answer aloud: mutable vs immutable, LEGB, 'is' vs '==', mutable default args. Speaking: Practise 'tell me about your AG Branch project': problem, role, action, result | K3: 6 | L3: docs.python.org/3/ (official tutorial, data model) | M3: 10 functions written without copying; all 4 interview answers given aloud in under 90 sec each | N3: Not Started | Q3: =IF(AND(N3="Completed",P3<>""),P3+3,"")
A4: 3 | B4: ='Learning Dashboard'!$B$3+A4-1 -> 46313 | C4: P1 Foundations | D4: Python | E4: Essential | F4: OOP 1: classes, instance/class/static methods, inheritance, polymorphism, encapsulation, ABCs | G4: Model a bank-account system with an abstract base class and 2 subclasses plus tests | H4: Hash maps: 3 easy (two-sum, anagram, frequency count) | I4: - | J4: Answer aloud: composition vs inheritance, ABC, 3 method types. Speaking: Think aloud while solving today's DSA problem (record it) | K4: 6 | L4: docs.python.org/3/ (official tutorial, data model) | M4: Working classes with tests; can explain composition vs inheritance with your own example | N4: Not Started | Q4: =IF(AND(N4="Completed",P4<>""),P4+3,"")
A5: 4 | B5: ='Learning Dashboard'!$B$3+A5-1 -> 46314 | C5: P1 Foundations | D5: Python | E5: Essential | F5: OOP 2: MRO, super(), multiple inheritance, dunder methods, properties, descriptors, dataclasses | G5: Build a Money class (__eq__, __add__, __repr__, validation property); convert to dataclass; write one custom descriptor | H5: Two pointers: 3 problems | I5: - | J5: Answer aloud: explain MRO with a diamond example. Speaking: Write one STAR story from real work | K5: 6 | L5: docs.python.org/3/ (official tutorial, data model) | M5: Money class passes tests; can draw a diamond MRO and predict super() order | N5: Not Started | Q5: =IF(AND(N5="Completed",P5<>""),P5+3,"")
A6: 5 | B6: ='Learning Dashboard'!$B$3+A6-1 -> 46315 | C6: P1 Foundations | D6: Python | E6: Essential | F6: Exceptions, custom exceptions, file handling, logging, pytest (fixtures, parametrize), mocking | G6: Custom exception hierarchy, context-managed file processor, pytest tests that mock an external API call | H6: Sliding window: 2 easy + 1 medium | I6: - | J6: Answer aloud: how do you test code that calls external services?. Speaking: Practise 'I don't know X, but here is how I would find out' | K6: 6 | L6: docs.python.org/3/ (official tutorial, data model) | M6: Tests pass with mocks; logging configured; explanation under 90 sec | N6: Not Started | Q6: =IF(AND(N6="Completed",P6<>""),P6+3,"")
A7: 6 | B7: ='Learning Dashboard'!$B$3+A7-1 -> 46316 | C7: P1 Foundations | D7: Python | E7: Essential | F7: Iterators, generators, decorators, closures, context managers | G7: Write a retry-with-backoff decorator, a generator pipeline for a large file, a timing context manager | H7: Prefix sums and hashing: 3 problems | I7: - | J7: Explain generators and decorators to a junior, 2 min each. Speaking: Practise asking clarifying questions on a vague prompt | K7: 6 | L7: docs.python.org/3/ (official tutorial, data model) | M7: All 3 utilities work with tests; explanation recorded and reviewed | N7: Not Started | Q7: =IF(AND(N7="Completed",P7<>""),P7+3,"")
A8: 7 | B8: ='Learning Dashboard'!$B$3+A8-1 -> 46317 | C8: P1 Foundations | D8: Review | E8: Essential | F8: Week 1 review and weekly test | G8: Closed-book test: 20 Python questions; redo your 3 weakest exercises; log gaps in Weak Areas | H8: Spaced reviews from DSA Log (1-3-7-21 rule) | I8: - | J8: Beginner mock round (Python) on the Mock Interviews tab; listen to recordings and note 3 errors | K8: 5 | L8: Weak Areas tab + earlier days' resources | M8: Test score recorded in Weekly Review; weak areas logged | N8: Not Started | Q8: =IF(AND(N8="Completed",P8<>""),P8+3,"")
A9: 8 | B9: ='Learning Dashboard'!$B$3+A9-1 -> 46318 | C9: P1 Foundations | D9: Databases | E9: Essential | F9: SQL 1: joins, aggregation, GROUP BY/HAVING, keys, constraints, relationships | G9: Design an e-commerce schema (users, products, orders, order_items) and write 10 queries | H9: Stacks and queues: 3 problems | I9: Schema design: e-commerce | J9: Answer aloud: INNER vs LEFT join, WHERE vs HAVING, primary vs unique key. Speaking: Re-record your 60-90 sec intro; fix tense errors | K9: 6 | L9: postgresql.org/docs (official) + Curriculum tab | M9: Schema created in Postgres; 10 queries return correct results | N9: Not Started | Q9: =IF(AND(N9="Completed",P9<>""),P9+3,"")
A10: 9 | B10: ='Learning Dashboard'!$B$3+A10-1 -> 46319 | C10: P1 Foundations | D10: Databases | E10: Essential | F10: SQL 2: subqueries, CTEs, set operations, window functions (ROW_NUMBER, RANK, LAG) | G10: Solve 15 SQL problems incl. top-N per group and running totals | H10: Linked lists and fast/slow pointers: 3 problems | I10: - | J10: Answer aloud: CTE vs subquery, RANK vs ROW_NUMBER. Speaking: Explain today's concept aloud in 2 min, then write 5 clear sentences | K10: 6 | L10: postgresql.org/docs (official) + Curriculum tab | M10: 12 of 15 solved independently; can explain each window function | N10: Not Started | Q10: =IF(AND(N10="Completed",P10<>""),P10+3,"")
A11: 10 | B11: ='Learning Dashboard'!$B$3+A11-1 -> 46320 | C11: P1 Foundations | D11: Databases | E11: Essential | F11: SQL 3: indexes (B-tree, composite), EXPLAIN ANALYZE, normalization vs denormalization. Phase 1 checkpoint | G11: Load 1M rows, run a slow query, add an index, compare plans and document the result | H11: Binary search: 3 problems | I11: - | J11: Answer aloud: why is this query slow and how would you fix it? Self-rate Phase 1. Speaking: Practise 'tell me about your AG Branch project': problem, role, action, result | K11: 6 | L11: postgresql.org/docs (official) + Curriculum tab | M11: Before/after plan documented; can explain composite-index column order | N11: Not Started | Q11: =IF(AND(N11="Completed",P11<>""),P11+3,"")
A12: 11 | B12: ='Learning Dashboard'!$B$3+A12-1 -> 46321 | C12: P2 Adv Python, Django & DRF | D12: Python | E12: Essential | F12: Concurrency: GIL, threading vs multiprocessing, asyncio/await, concurrency vs parallelism | G12: Run one I/O task and one CPU task with threads, asyncio and multiprocessing; measure and record results | H12: Recursion: 3 problems | I12: - | J12: Answer aloud: when asyncio vs threads vs processes?. Speaking: Think aloud while solving today's DSA problem (record it) | K12: 6 | L12: docs.python.org/3/ (official tutorial, data model) | M12: Measured results in notes; clear 2-min explanation of the GIL | N12: Not Started | Q12: =IF(AND(N12="Completed",P12<>""),P12+3,"")
A13: 12 | B13: ='Learning Dashboard'!$B$3+A13-1 -> 46322 | C13: P2 Adv Python, Django & DRF | D13: Django | E13: Essential | F13: Django architecture: project/app layout, request-response lifecycle, URLs, views, middleware, settings, environment config, REST/HTTP semantics | G13: Create a project with split settings, custom middleware (request ID + timing), env-based secrets | H13: Sorting and intervals: 3 problems | I13: Layered structure: views, services, selectors | J13: Answer aloud: walk through a Django request from URL to response. Speaking: Write one STAR story from real work | K13: 6 | L13: docs.djangoproject.com (official docs) | M13: Project runs; middleware tested; lifecycle explained without notes | N13: Not Started | Q13: =IF(AND(N13="Completed",P13<>""),P13+3,"")
... A61: 60 | B61: ='Learning Dashboard'!$B$3+A61-1 -> 46370 | C61: P6 Revision & Mocks | D61: Assessment | E61: Essential | F61: Day-60 final assessment, readiness report and next-30-day plan | G61: Timed final assessment. Enter Day 60 levels. Write a one-page readiness report: levels with evidence, roles ready for, top 3 gaps. | H61: Timed: 2 problems | I61: - | J61: Compare intro with Day 1 recording | K61: 6 | L61: Skill Assessment + Mock Interviews tabs | M61: Day 60 levels entered; readiness report written from evidence only | N61: Not Started | Q61: =IF(AND(N61="Completed",P61<>""),P61+3,"")
A63: Rules: never mark Completed until the Completion criteria are met with evidence (code, tests, a solved problem, a recorded explanation). Next revision = completed date + 3 days (DSA problems use 1-3-7-21 on the DSA Log tab). Missed days: see Daily Schedule tab.

Sheet 30-Day Accelerated
A1: Day | B1: Date | C1: 60-Day plan days covered | D1: Topics (essentials only) | E1: Depth target | F1: Est. hrs | G1: Status | H1: Confidence (1-5) | I1: Completed on | J1: Weaknesses / notes
A2: 1 | B2: ='Learning Dashboard'!$B$3+A2-1 -> 46311 | C2: Days 1-2 | D2: ='60-Day Plan'!F2&" + "&'60-Day Plan'!F3 -> Baseline assessment and environment setup + Data types, mutability, comprehensions, functions, *args/**kwargs, scope (LEGB), shallow vs deep copy | E2: Concept + interview-level explanation. Implement only the core exercise; skip Optional items and project polish. | F2: 7 | G2: Not Started
A3: 2 | B3: ='Learning Dashboard'!$B$3+A3-1 -> 46312 | C3: Days 3-4 | D3: ='60-Day Plan'!F4&" + "&'60-Day Plan'!F5 -> OOP 1: classes, instance/class/static methods, inheritance, polymorphism, encapsulation, ABCs + OOP 2: MRO, super(), multiple inheritance, dunder methods, properties, descriptors, dataclasses | E3: Concept + interview-level explanation. Implement only the core exercise; skip Optional items and project polish. | F3: 7 | G3: Not Started
A4: 3 | B4: ='Learning Dashboard'!$B$3+A4-1 -> 46313 | C4: Days 5-6 | D4: ='60-Day Plan'!F6&" + "&'60-Day Plan'!F7 -> Exceptions, custom exceptions, file handling, logging, pytest (fixtures, parametrize), mocking + Iterators, generators, decorators, closures, context managers | E4: Concept + interview-level explanation. Implement only the core exercise; skip Optional items and project polish. | F4: 7 | G4: Not Started
A5: 4 | B5: ='Learning Dashboard'!$B$3+A5-1 -> 46314 | C5: Days 7-8 | D5: ='60-Day Plan'!F8&" + "&'60-Day Plan'!F9 -> Week 1 review and weekly test + SQL 1: joins, aggregation, GROUP BY/HAVING, keys, constraints, relationships | E5: Concept + interview-level explanation. Implement only the core exercise; skip Optional items and project polish. | F5: 7 | G5: Not Started
A6: 5 | B6: ='Learning Dashboard'!$B$3+A6-1 -> 46315 | C6: Days 9-10 | D6: ='60-Day Plan'!F10&" + "&'60-Day Plan'!F11 -> SQL 2: subqueries, CTEs, set operations, window functions (ROW_NUMBER, RANK, LAG) + SQL 3: indexes (B-tree, composite), EXPLAIN ANALYZE, normalization vs denormalization. Phase 1 checkpoint | E6: Concept + interview-level explanation. Implement only the core exercise; skip Optional items and project polish. | F6: 7 | G6: Not Started
A7: 6 | B7: ='Learning Dashboard'!$B$3+A7-1 -> 46316 | C7: Days 11-12 | D7: ='60-Day Plan'!F12&" + "&'60-Day Plan'!F13 -> Concurrency: GIL, threading vs multiprocessing, asyncio/await, concurrency vs parallelism + Django architecture: project/app layout, request-response lifecycle, URLs, views, middleware, settings, environment config, REST/HTTP semantics | E7: Concept + interview-level explanation. Implement only the core exercise; skip Optional items and project polish. | F7: 7 | G7: Not Started
A8: 7 | B8: ='Learning Dashboard'!$B$3+A8-1 -> 46317 | C8: Days 13-14 | D8: ='60-Day Plan'!F14&" + "&'60-Day Plan'!F15 -> Django ORM deep dive: lazy QuerySets, managers, F/Q, annotate/aggregate, subqueries, select_related/prefetch_related, N+1 + Week 2 review and weekly test | E8: Concept + interview-level explanation. Implement only the core exercise; skip Optional items and project polish. | F8: 7 | G8: Not Started
A9: 8 | B9: ='Learning Dashboard'!$B$3+A9-1 -> 46318 | C9: Days 15-16 | D9: ='60-Day Plan'!F16&" + "&'60-Day Plan'!F17 -> Day-15 assessment and weak-area fix + Models, relationships, migrations, transactions (atomic, select_for_update), signals and their pitfalls | E9: Concept + interview-level explanation. Implement only the core exercise; skip Optional items and project polish. | F9: 7 | G9: Not Started
A10: 9 | B10: ='Learning Dashboard'!$B$3+A10-1 -> 46319 | C10: Days 17-18 | D10: ='60-Day Plan'!F18&" + "&'60-Day Plan'!F19 -> Auth: sessions, custom user model, groups/permissions, Django admin, caching, pagination and filtering + DRF core: serializers (validation, nested), APIView, generic views, viewsets, routers | E10: Concept + interview-level explanation. Implement only the core exercise; skip Optional items and project polish. | F10: 7 | G10: Not Started
A11: 10 | B11: ='Learning Dashboard'!$B$3+A11-1 -> 46320 | C11: Days 19-20 | D11: ='60-Day Plan'!F20&" + "&'60-Day Plan'!F21 -> DRF: JWT auth, permissions, throttling, versioning, exception handling, OpenAPI docs + DRF testing, security (CSRF, CORS, SQL injection), performance, ASGI vs WSGI. Optional: Channels/WebSockets intro | E11: Concept + interview-level explanation. Implement only the core exercise; skip Optional items and project polish. | F11: 7 | G11: Not Started
A12: 11 | B12: ='Learning Dashboard'!$B$3+A12-1 -> 46321 | C12: Days 21-22 | D12: ='60-Day Plan'!F22&" + "&'60-Day Plan'!F23 -> Week 3 review and weekly test + FastAPI 1: ASGI, routing, path/query/body params, Pydantic models, response models | E12: Concept + interview-level explanation. Implement only the core exercise; skip Optional items and project polish. | F12: 7 | G12: Not Started
A13: 12 | B13: ='Learning Dashboard'!$B$3+A13-1 -> 46322 | C13: Days 23-24 | D13: ='60-Day Plan'!F24&" + "&'60-Day Plan'!F25 -> FastAPI 2: dependency injection and overrides, OAuth2 password flow, JWT, role-based authorization + FastAPI 3: SQLAlchemy 2.0 + Alembic, sessions, transactions, sync vs async endpoints, pagination and filtering | E13: Concept + interview-level explanation. Implement only the core exercise; skip Optional items and project polish. | F13: 7 | G13: Not Started
A14: 13 | B14: ='Learning Dashboard'!$B$3+A14-1 -> 46323 | C14: Days 25-26 | D14: ='60-Day Plan'!F26&" + "&'60-Day Plan'!F27 -> FastAPI 4: pytest and TestClient, overrides, pydantic-settings config, middleware, exception handlers, background tasks and their limits, Docker + Redis and caching: data structures, cache-aside/write-through/write-behind, TTL, eviction, stampedes, rate limiting | E14: Concept + interview-level explanation. Implement only the core exercise; skip Optional items and project polish. | F14: 7 | G14: Not Started
A15: 14 | B15: ='Learning Dashboard'!$B$3+A15-1 -> 46324 | C15: Days 27-28 | D15: ='60-Day Plan'!F28&" + "&'60-Day Plan'!F29 -> Celery and messaging: workers, brokers, retries, backoff, idempotency, dead-letter queues, at-least-once delivery, periodic tasks, Redis vs RabbitMQ + Week 4 review and weekly test | E15: Concept + interview-level explanation. Implement only the core exercise; skip Optional items and project polish. | F15: 7 | G15: Not Started
A16: 15 | B16: ='Learning Dashboard'!$B$3+A16-1 -> 46325 | C16: Days 29-30 | D16: ='60-Day Plan'!F30&" + "&'60-Day Plan'!F31 -> Project B: async FastAPI service with external API integration, caching, background jobs, transactions, structured logging, error handling + Day-30 assessment, mock interview 1 and interview checkpoint | E16: Concept + interview-level explanation. Implement only the core exercise; skip Optional items and project polish. | F16: 7 | G16: Not Started
A17: 16 | B17: ='Learning Dashboard'!$B$3+A17-1 -> 46326 | C17: Days 31-32 | D17: ='60-Day Plan'!F32&" + "&'60-Day Plan'!F33 -> Linux and networking: commands, permissions, processes, ports, DNS, HTTP/HTTPS, TCP/IP, TLS, reverse proxy and load balancer concepts, logs + System design foundations: requirements, capacity estimation, latency/throughput/availability, API and data model, caching, queues, load balancers, replication | E17: Concept + interview-level explanation. Implement only the core exercise; skip Optional items and project polish. | F17: 7 | G17: Not Started
A18: 17 | B18: ='Learning Dashboard'!$B$3+A18-1 -> 46327 | C18: Days 33-34 | D18: ='60-Day Plan'!F34&" + "&'60-Day Plan'!F35 -> Docker: images, layers, Dockerfile, multi-stage builds, volumes, networks, Compose, health checks, secrets + Production containers: gunicorn/uvicorn workers, Nginx reverse proxy, non-root user, env config | E18: Concept + interview-level explanation. Implement only the core exercise; skip Optional items and project polish. | F18: 7 | G18: Not Started
A19: 18 | B19: ='Learning Dashboard'!$B$3+A19-1 -> 46328 | C19: Days 35-36 | D19: ='60-Day Plan'!F36&" + "&'60-Day Plan'!F37 -> Week 5 review and weekly test + Design exercise 1: URL shortener and rate limiter | E19: Concept + interview-level explanation. Implement only the core exercise; skip Optional items and project polish. | F19: 7 | G19: Not Started
A20: 19 | B20: ='Learning Dashboard'!$B$3+A20-1 -> 46329 | C20: Days 37-38 | D20: ='60-Day Plan'!F38&" + "&'60-Day Plan'!F39 -> Database scaling: replication, read replicas, partitioning, sharding, connection pooling, backups, SQL vs NoSQL, eventual consistency + Git workflows and CI: GitHub Actions for lint, tests, image build | E20: Concept + interview-level explanation. Implement only the core exercise; skip Optional items and project polish. | F20: 7 | G20: Not Started
A21: 20 | B21: ='Learning Dashboard'!$B$3+A21-1 -> 46330 | C21: Days 39-40 | D21: ='60-Day Plan'!F40&" + "&'60-Day Plan'!F41 -> Design exercise 2: notification service and background job processing + DSA checkpoint and integrated backend scenarios | E21: Concept + interview-level explanation. Implement only the core exercise; skip Optional items and project polish. | F21: 7 | G21: Not Started
A22: 21 | B22: ='Learning Dashboard'!$B$3+A22-1 -> 46331 | C22: Days 41-42 | D22: ='60-Day Plan'!F42&" + "&'60-Day Plan'!F43 -> Cloud foundations: shared responsibility, compute/network/storage/IAM/managed DB, VPC, security groups, load balancers, autoscaling, monitoring; choose one primary cloud and map to the others + Week 6 review and weekly test | E22: Concept + interview-level explanation. Implement only the core exercise; skip Optional items and project polish. | F22: 7 | G22: Not Started
A23: 22 | B23: ='Learning Dashboard'!$B$3+A23-1 -> 46332 | C23: Days 43-44 | D23: ='60-Day Plan'!F44&" + "&'60-Day Plan'!F45 -> Cloud hands-on 1 (free tier): IAM least privilege, object storage with pre-signed URLs, budgets and alerts, cost and cleanup + Deploy one project to a public URL (cost-safe) | E23: Concept + interview-level explanation. Implement only the core exercise; skip Optional items and project polish. | F23: 7 | G23: Not Started
A24: 23 | B24: ='Learning Dashboard'!$B$3+A24-1 -> 46333 | C24: Days 45-46 | D24: ='60-Day Plan'!F46&" + "&'60-Day Plan'!F47 -> Day-45 assessment and mock interview 2 + CI/CD to deployment: build, test, push image, deploy, migrations during deploy, rollback, blue-green and rolling basics | E24: Concept + interview-level explanation. Implement only the core exercise; skip Optional items and project polish. | F24: 7 | G24: Not Started
A25: 24 | B25: ='Learning Dashboard'!$B$3+A25-1 -> 46334 | C25: Days 47-48 | D25: ='60-Day Plan'!F48&" + "&'60-Day Plan'!F49 -> Reliability: timeouts, retries, circuit breakers, bulkheads, graceful degradation, idempotent APIs, distributed locks, outbox, saga, monolith vs microservices + Observability: structured logs, metrics, traces, alerts, health and readiness endpoints | E25: Concept + interview-level explanation. Implement only the core exercise; skip Optional items and project polish. | F25: 7 | G25: Not Started
A26: 25 | B26: ='Learning Dashboard'!$B$3+A26-1 -> 46335 | C26: Days 49-50 | D26: ='60-Day Plan'!F50&" + "&'60-Day Plan'!F51 -> Week 7 review and weekly test + Integrated project day: deployment docs, README, architecture decision records. Design exercise 3: e-commerce backend | E26: Concept + interview-level explanation. Implement only the core exercise; skip Optional items and project polish. | F26: 7 | G26: Not Started
A27: 26 | B27: ='Learning Dashboard'!$B$3+A27-1 -> 46336 | C27: Days 51-52 | D27: ='60-Day Plan'!F52&" + "&'60-Day Plan'!F53 -> Design exercise 4: chat service and booking system + Weak-area remediation 1: Python and Django | E27: Concept + interview-level explanation. Implement only the core exercise; skip Optional items and project polish. | F27: 7 | G27: Not Started
A28: 27 | B28: ='Learning Dashboard'!$B$3+A28-1 -> 46337 | C28: Days 53-54 | D28: ='60-Day Plan'!F54&" + "&'60-Day Plan'!F55 -> Weak-area remediation 2: SQL, databases and backend + DSA weak patterns and timed mock | E28: Concept + interview-level explanation. Implement only the core exercise; skip Optional items and project polish. | F28: 7 | G28: Not Started
A29: 28 | B29: ='Learning Dashboard'!$B$3+A29-1 -> 46338 | C29: Days 55-56 | D29: ='60-Day Plan'!F56&" + "&'60-Day Plan'!F57 -> Mock interview 3: Python/Django + SQL + coding + Week 8 review and weekly test | E29: Concept + interview-level explanation. Implement only the core exercise; skip Optional items and project polish. | F29: 7 | G29: Not Started
A30: 29 | B30: ='Learning Dashboard'!$B$3+A30-1 -> 46339 | C30: Days 57-58 | D30: ='60-Day Plan'!F58&" + "&'60-Day Plan'!F59 -> Mock interview 4: system design, behavioural and project deep-dive + Project stories, CV and portfolio update, English polish | E30: Concept + interview-level explanation. Implement only the core exercise; skip Optional items and project polish. | F30: 7 | G30: Not Started
A31: 30 | B31: ='Learning Dashboard'!$B$3+A31-1 -> 46340 | C31: Days 59-60 | D31: ='60-Day Plan'!F60&" + "&'60-Day Plan'!F61 -> Final full mock loop: 3 rounds back-to-back + Day-60 final assessment, readiness report and next-30-day plan | E31: Concept + interview-level explanation. Implement only the core exercise; skip Optional items and project polish. | F31: 7 | G31: Not Started
A33: Use this INSTEAD of the 60-Day Plan only if you must. It covers two plan-days per day at conceptual and interview depth, so it reaches Level 3 (not Level 4) in most subjects. Use the 60-Day Plan's exercises for the detail of each pair. Do not mix both plans' statuses.

Sheet Daily Schedule
A1: Daily schedule, fallbacks and recovery rules
A2: Minutes are targets, not rules. Edit the yellow cells to fit your family routine.
A4: Block (normal day, about 6 hrs) | B4: Minutes | C4: Suggested time | D4: What to do | E4: Fallback (3 hrs) min
A5: Core concept (Python/Django/DB/backend) | B5: 90 | C5: 09:00 | D5: Read official docs or notes, then explain in your own words before coding | E5: 60
A6: DSA / problem solving | B6: 60 | C6: 10:45 | D6: Attempt first, explain approach, edge cases, complexity BEFORE checking solution | E6: 40
A7: Hands-on coding / project | B7: 60 | C7: 12:00 | D7: Build or extend the project milestone for the day | E7: 40
A8: Design or deployment | B8: 45 | C8: 15:00 | D8: System design exercise or Docker/cloud task (see plan column) | E8: 0
A9: Communication / interview practice | B9: 30 | C9: 16:00 | D9: Speak aloud, record, review one recording | E9: 0
A10: Revision and active recall | B10: 30 | C10: 16:45 | D10: Close the notes and answer yesterday's questions; log mistakes | E10: 20
A11: Job search window | B11: 40 | C11: 17:30 | D11: About 5 quality outreach messages, 2 relevant applications, 3 follow-ups | E11: 20
A12: Total minutes | B12: =SUM(B5:B11) -> 355 | E12: =SUM(E5:E11) -> 180
A13: Total hours | B13: =B12/60 -> 5.9166667 | E13: =E12/60 -> 3
A14: Add 10-minute breaks between blocks and one real break for family. Stop when blocks are done. Sleep and rest are part of the plan.
A16: Low-energy day (minimum viable, about 90 min) | B16: Minutes | D16: What counts
A17: Core topic: read + write 5 bullet notes | B17: 30 | D17: Just understanding, no pressure to finish exercises
A18: 1 easy DSA problem OR review one old one | B18: 25 | D18: Explain it aloud in 2 minutes
A19: Active recall: 5 questions | B19: 20 | D19: From yesterday's topic, no notes
A20: Job follow-ups | B20: 15 | D20: Follow up on 3-5 existing leads, nothing new
A21: A minimum day is a SUCCESSFUL day. Mark the plan row 'In Progress', never failed.
A23: Recovery and adjustment rules | D23: Rule
A24: Missed 1 day | D24: Do only the Essential parts (core topic + DSA) of the missed day. Skip Optional items.
A25: Missed 2-3 days | D25: Use the next Review day as catch-up. Do not double up on new material.
A26: Missed more than 3 days | D26: Shift the plan end date. Drop Optional items and Advanced extensions. Never restart from Day 1.
A27: Interview invitation | D27: 1) Accept. 2) List the role's required skills. 3) Give the next 1-2 days about 60% to role-specific prep, keep 30 min of DSA and job outreach. 4) After it, log it on Mock Interviews as a REAL interview and add gaps to Weak Areas. 5) Resume the plan.
A28: Paid project offer | D28: Accept only if scope is written, 50% upfront, and it fits about 10-15 hrs/week. Then drop Optional items, keep core topic + DSA minimum, and extend the end date by the hours given.
A29: Not ready yet? | D29: Use the readiness checkpoints on the Dashboard. You do not need to wait for Day 60 to interview for roles you honestly match.

Sheet Daily Log
A1: Day | B1: Date | C1: Day type | D1: Outreach sent | E1: Applications | F1: Follow-ups | G1: Interview prep (min) | H1: Learning (min) | I1: Low-value time (min) | J1: Energy | K1: Main win / blocker | L1: Learning day # | M1: Core topic done? | N1: DSA done? | O1: Hands-on done? | P1: Design / deploy done? | Q1: Speaking practice done? | R1: Active recall done?
A2: 1 | B2: ='Start Here'!$B$3+A2-1 -> 46309 | L2: =IF(B2>='Learning Dashboard'!$B$3,B2-'Learning Dashboard'!$B$3+1,"")
A3: 2 | B3: ='Start Here'!$B$3+A3-1 -> 46310 | L3: =IF(B3>='Learning Dashboard'!$B$3,B3-'Learning Dashboard'!$B$3+1,"")
A4: 3 | B4: ='Start Here'!$B$3+A4-1 -> 46311 | L4: =IF(B4>='Learning Dashboard'!$B$3,B4-'Learning Dashboard'!$B$3+1,"") -> 1
A5: 4 | B5: ='Start Here'!$B$3+A5-1 -> 46312 | L5: =IF(B5>='Learning Dashboard'!$B$3,B5-'Learning Dashboard'!$B$3+1,"") -> 2
A6: 5 | B6: ='Start Here'!$B$3+A6-1 -> 46313 | L6: =IF(B6>='Learning Dashboard'!$B$3,B6-'Learning Dashboard'!$B$3+1,"") -> 3
A7: 6 | B7: ='Start Here'!$B$3+A7-1 -> 46314 | L7: =IF(B7>='Learning Dashboard'!$B$3,B7-'Learning Dashboard'!$B$3+1,"") -> 4
A8: 7 | B8: ='Start Here'!$B$3+A8-1 -> 46315 | L8: =IF(B8>='Learning Dashboard'!$B$3,B8-'Learning Dashboard'!$B$3+1,"") -> 5
A9: 8 | B9: ='Start Here'!$B$3+A9-1 -> 46316 | L9: =IF(B9>='Learning Dashboard'!$B$3,B9-'Learning Dashboard'!$B$3+1,"") -> 6
A10: 9 | B10: ='Start Here'!$B$3+A10-1 -> 46317 | L10: =IF(B10>='Learning Dashboard'!$B$3,B10-'Learning Dashboard'!$B$3+1,"") -> 7
A11: 10 | B11: ='Start Here'!$B$3+A11-1 -> 46318 | L11: =IF(B11>='Learning Dashboard'!$B$3,B11-'Learning Dashboard'!$B$3+1,"") -> 8
A12: 11 | B12: ='Start Here'!$B$3+A12-1 -> 46319 | L12: =IF(B12>='Learning Dashboard'!$B$3,B12-'Learning Dashboard'!$B$3+1,"") -> 9
A13: 12 | B13: ='Start Here'!$B$3+A13-1 -> 46320 | L13: =IF(B13>='Learning Dashboard'!$B$3,B13-'Learning Dashboard'!$B$3+1,"") -> 10
... A91: 90 | B91: ='Start Here'!$B$3+A91-1 -> 46398 | L91: =IF(B91>='Learning Dashboard'!$B$3,B91-'Learning Dashboard'!$B$3+1,"") -> 88
C93: Daily targets (normal day): | D93: 5 | E93: 2 | F93: 3 | G93: 60 | H93: 60 | I93: 30
C94: Low-energy day minimum: 5 follow-ups, 1 interview question, then rest.
A95: Daily targets were changed on 15-Oct-26 (see Change Log). Columns L-R are the daily learning checklist.

Sheet Curriculum
A1: ID | B1: Module | C1: Topic | D1: Tier | E1: Plan day(s) | F1: Status | G1: Level (1-5) | H1: Evidence (code / test / problem / explanation) | I1: Notes
A2: 1 | B2: 1 Python | C2: Variables, data types, collections, comprehensions | D2: Master first | E2: D2 | F2: Not Started
A3: 2 | B3: 1 Python | C3: Functions, args, scope (LEGB), closures, copy semantics | D3: Master first | E3: D2 | F3: Not Started
A4: 3 | B4: 1 Python | C4: OOP: classes, methods, inheritance, polymorphism, ABCs | D4: Master first | E4: D3 | F4: Not Started
A5: 4 | B5: 1 Python | C5: Composition vs inheritance | D5: Master first | E5: D3 | F5: Not Started
A6: 5 | B6: 1 Python | C6: MRO, super(), dunder methods | D6: Master first | E6: D4 | F6: Not Started
A7: 6 | B7: 1 Python | C7: Properties, descriptors, dataclasses | D7: Understand conceptually | E7: D4 | F7: Not Started
A8: 7 | B8: 1 Python | C8: Exceptions, custom exceptions, logging | D8: Master first | E8: D5 | F8: Not Started
A9: 8 | B9: 1 Python | C9: Testing: pytest, fixtures, mocking | D9: Master first | E9: D5 | F9: Not Started
A10: 9 | B10: 1 Python | C10: Iterators and generators | D10: Master first | E10: D6 | F10: Not Started
A11: 10 | B11: 1 Python | C11: Decorators and context managers | D11: Master first | E11: D6 | F11: Not Started
A12: 11 | B12: 1 Python | C12: GIL, threading, multiprocessing, asyncio | D12: Master first | E12: D11 | F12: Not Started
A13: 12 | B13: 1 Python | C13: Type hints, generics, protocols | D13: Understand conceptually | E13: D11 | F13: Not Started
... A139: 138 | B139: 9 Communication | C139: Mock interview practice | D139: Master first | E139: D30, D45, D55-D59 | F139: Not Started
B141: Tiers: 'Master first' = expect questions in interviews; 'Understand conceptually' = know trade-offs, implement if time; 'Advanced extension' = later phase.
B142: Level scale: 1 Awareness, 2 Understanding, 3 Independent implementation, 4 Interview-ready, 5 Advanced application (see Skill Assessment).

Sheet Skill Assessment
A1: Skill assessment (levels 1-5, evidence required)
A2: Enter a level only when you have evidence (working code, passing tests, solved problem, accurate explanation, completed design). Yellow cells are yours.
A3: Subject | B3: Interview round | C3: Weight | D3: Target level | E3: Baseline | F3: Day 15 | G3: Day 30 | H3: Day 45 | I3: Day 60 | J3: Current level | K3: Gap | L3: Ready? | M3: Score %
A4: Python | B4: Python & Django interview | C4: 15 | D4: 4 | J4: =IF(I4<>"",I4,IF(H4<>"",H4,IF(G4<>"",G4,IF(F4<>"",F4,IF(E4<>"",E4,""))))) | K4: =IF(J4="","",D4-J4) | L4: =IF(J4="","Not assessed",IF(J4>=D4,"Ready","Not yet")) -> Not assessed | M4: =IF(J4="",0,MIN(J4,D4)/D4) -> 0
A5: Django & DRF | B5: Python & Django interview | C5: 20 | D5: 4 | J5: =IF(I5<>"",I5,IF(H5<>"",H5,IF(G5<>"",G5,IF(F5<>"",F5,IF(E5<>"",E5,""))))) | K5: =IF(J5="","",D5-J5) | L5: =IF(J5="","Not assessed",IF(J5>=D5,"Ready","Not yet")) -> Not assessed | M5: =IF(J5="",0,MIN(J5,D5)/D5) -> 0
A6: FastAPI | B6: Python & Django interview | C6: 8 | D6: 3 | J6: =IF(I6<>"",I6,IF(H6<>"",H6,IF(G6<>"",G6,IF(F6<>"",F6,IF(E6<>"",E6,""))))) | K6: =IF(J6="","",D6-J6) | L6: =IF(J6="","Not assessed",IF(J6>=D6,"Ready","Not yet")) -> Not assessed | M6: =IF(J6="",0,MIN(J6,D6)/D6) -> 0
A7: Databases & SQL | B7: Database & backend round | C7: 15 | D7: 4 | J7: =IF(I7<>"",I7,IF(H7<>"",H7,IF(G7<>"",G7,IF(F7<>"",F7,IF(E7<>"",E7,""))))) | K7: =IF(J7="","",D7-J7) | L7: =IF(J7="","Not assessed",IF(J7>=D7,"Ready","Not yet")) -> Not assessed | M7: =IF(J7="",0,MIN(J7,D7)/D7) -> 0
A8: Advanced Backend | B8: Database & backend round | C8: 10 | D8: 3 | J8: =IF(I8<>"",I8,IF(H8<>"",H8,IF(G8<>"",G8,IF(F8<>"",F8,IF(E8<>"",E8,""))))) | K8: =IF(J8="","",D8-J8) | L8: =IF(J8="","Not assessed",IF(J8>=D8,"Ready","Not yet")) -> Not assessed | M8: =IF(J8="",0,MIN(J8,D8)/D8) -> 0
A9: Docker, Cloud & CI/CD | B9: Deployment & cloud questions | C9: 7 | D9: 3 | J9: =IF(I9<>"",I9,IF(H9<>"",H9,IF(G9<>"",G9,IF(F9<>"",F9,IF(E9<>"",E9,""))))) | K9: =IF(J9="","",D9-J9) | L9: =IF(J9="","Not assessed",IF(J9>=D9,"Ready","Not yet")) -> Not assessed | M9: =IF(J9="",0,MIN(J9,D9)/D9) -> 0
A10: DSA | B10: DSA assessment | C10: 10 | D10: 3 | J10: =IF(I10<>"",I10,IF(H10<>"",H10,IF(G10<>"",G10,IF(F10<>"",F10,IF(E10<>"",E10,""))))) | K10: =IF(J10="","",D10-J10) | L10: =IF(J10="","Not assessed",IF(J10>=D10,"Ready","Not yet")) -> Not assessed | M10: =IF(J10="",0,MIN(J10,D10)/D10) -> 0
A11: System Design | B11: System design round | C11: 10 | D11: 3 | J11: =IF(I11<>"",I11,IF(H11<>"",H11,IF(G11<>"",G11,IF(F11<>"",F11,IF(E11<>"",E11,""))))) | K11: =IF(J11="","",D11-J11) | L11: =IF(J11="","Not assessed",IF(J11>=D11,"Ready","Not yet")) -> Not assessed | M11: =IF(J11="",0,MIN(J11,D11)/D11) -> 0
A12: Communication | B12: Behavioural & communication round | C12: 5 | D12: 4 | J12: =IF(I12<>"",I12,IF(H12<>"",H12,IF(G12<>"",G12,IF(F12<>"",F12,IF(E12<>"",E12,""))))) | K12: =IF(J12="","",D12-J12) | L12: =IF(J12="","Not assessed",IF(J12>=D12,"Ready","Not yet")) -> Not assessed | M12: =IF(J12="",0,MIN(J12,D12)/D12) -> 0
A14: Weighted readiness score | C14: =SUM(C4:C12) -> 100 | M14: =IFERROR(SUMPRODUCT(C4:C12,M4:M12)/C14,0) -> 0
A15: Weights and target levels are my provisional assumptions for Python backend roles. Change them to match your target jobs. Weights should total 100.
A17: Level | B17: Name | D17: What it means
A18: 1 | B18: Awareness | D18: I recognise the concept but cannot explain it reliably.
A19: 2 | B19: Understanding | D19: I can explain the basics and follow examples.
A20: 3 | B20: Independent implementation | D20: I can solve practical tasks with limited help.
A21: 4 | B21: Interview-ready | D21: I can explain trade-offs, solve relevant problems and answer follow-ups independently.
A22: 5 | B22: Advanced application | D22: I can handle complex scenarios, diagnose issues and justify engineering decisions.
A24: Reading or watching a tutorial is not evidence. Evidence = working code, passing tests, a solved problem, an accurate recorded explanation, or a completed design exercise.

Sheet DSA Log
A1: # | B1: Date | C1: Problem | D1: Pattern | E1: Difficulty | F1: Source | G1: Explained approach first? | H1: Edge cases listed? | I1: Solved without hint? | J1: Time (min) | K1: Time/space stated? | L1: Review 1 (+1d) | M1: Review 2 (+3d) | N1: Review 3 (+7d) | O1: Review 4 (+21d) | P1: Reviews done (0-4) | Q1: Next review due | R1: Notes / mistake
A2: 1 | B2: 46027 | C2: Two Sum (delete me) | D2: Hash map | E2: Easy | F2: Practice | G2: Yes | H2: Yes | I2: Yes | J2: 12 | K2: Yes | L2: =IF($B2="","",$B2+1) -> 46028 | M2: =IF($B2="","",$B2+3) -> 46030 | N2: =IF($B2="","",$B2+7) -> 46034 | O2: =IF($B2="","",$B2+21) -> 46048 | P2: 0 | Q2: =IF($B2="","",IF(P2>=4,"Done",CHOOSE(P2+1,L2,M2,N2,O2))) -> 46028
A3: 2 | L3: =IF($B3="","",$B3+1) | M3: =IF($B3="","",$B3+3) | N3: =IF($B3="","",$B3+7) | O3: =IF($B3="","",$B3+21) | Q3: =IF($B3="","",IF(P3>=4,"Done",CHOOSE(P3+1,L3,M3,N3,O3)))
A4: 3 | L4: =IF($B4="","",$B4+1) | M4: =IF($B4="","",$B4+3) | N4: =IF($B4="","",$B4+7) | O4: =IF($B4="","",$B4+21) | Q4: =IF($B4="","",IF(P4>=4,"Done",CHOOSE(P4+1,L4,M4,N4,O4)))
A5: 4 | L5: =IF($B5="","",$B5+1) | M5: =IF($B5="","",$B5+3) | N5: =IF($B5="","",$B5+7) | O5: =IF($B5="","",$B5+21) | Q5: =IF($B5="","",IF(P5>=4,"Done",CHOOSE(P5+1,L5,M5,N5,O5)))
A6: 5 | L6: =IF($B6="","",$B6+1) | M6: =IF($B6="","",$B6+3) | N6: =IF($B6="","",$B6+7) | O6: =IF($B6="","",$B6+21) | Q6: =IF($B6="","",IF(P6>=4,"Done",CHOOSE(P6+1,L6,M6,N6,O6)))
A7: 6 | L7: =IF($B7="","",$B7+1) | M7: =IF($B7="","",$B7+3) | N7: =IF($B7="","",$B7+7) | O7: =IF($B7="","",$B7+21) | Q7: =IF($B7="","",IF(P7>=4,"Done",CHOOSE(P7+1,L7,M7,N7,O7)))
A8: 7 | L8: =IF($B8="","",$B8+1) | M8: =IF($B8="","",$B8+3) | N8: =IF($B8="","",$B8+7) | O8: =IF($B8="","",$B8+21) | Q8: =IF($B8="","",IF(P8>=4,"Done",CHOOSE(P8+1,L8,M8,N8,O8)))
A9: 8 | L9: =IF($B9="","",$B9+1) | M9: =IF($B9="","",$B9+3) | N9: =IF($B9="","",$B9+7) | O9: =IF($B9="","",$B9+21) | Q9: =IF($B9="","",IF(P9>=4,"Done",CHOOSE(P9+1,L9,M9,N9,O9)))
A10: 9 | L10: =IF($B10="","",$B10+1) | M10: =IF($B10="","",$B10+3) | N10: =IF($B10="","",$B10+7) | O10: =IF($B10="","",$B10+21) | Q10: =IF($B10="","",IF(P10>=4,"Done",CHOOSE(P10+1,L10,M10,N10,O10)))
A11: 10 | L11: =IF($B11="","",$B11+1) | M11: =IF($B11="","",$B11+3) | N11: =IF($B11="","",$B11+7) | O11: =IF($B11="","",$B11+21) | Q11: =IF($B11="","",IF(P11>=4,"Done",CHOOSE(P11+1,L11,M11,N11,O11)))
A12: 11 | L12: =IF($B12="","",$B12+1) | M12: =IF($B12="","",$B12+3) | N12: =IF($B12="","",$B12+7) | O12: =IF($B12="","",$B12+21) | Q12: =IF($B12="","",IF(P12>=4,"Done",CHOOSE(P12+1,L12,M12,N12,O12)))
A13: 12 | L13: =IF($B13="","",$B13+1) | M13: =IF($B13="","",$B13+3) | N13: =IF($B13="","",$B13+7) | O13: =IF($B13="","",$B13+21) | Q13: =IF($B13="","",IF(P13>=4,"Done",CHOOSE(P13+1,L13,M13,N13,O13)))
A14: 13 | L14: =IF($B14="","",$B14+1) | M14: =IF($B14="","",$B14+3) | N14: =IF($B14="","",$B14+7) | O14: =IF($B14="","",$B14+21) | Q14: =IF($B14="","",IF(P14>=4,"Done",CHOOSE(P14+1,L14,M14,N14,O14)))
... A201: 200 | L201: =IF($B201="","",$B201+1) | M201: =IF($B201="","",$B201+3) | N201: =IF($B201="","",$B201+7) | O201: =IF($B201="","",$B201+21) | Q201: =IF($B201="","",IF(P201>=4,"Done",CHOOSE(P201+1,L201,M201,N201,O201)))
A204: Rules: attempt first; explain approach, edge cases and complexity BEFORE checking the solution. Review dates are formulas (1, 3, 7, 21 days). Red Next review due = due today or overdue. Row 2 is an example and is not counted.

Sheet Mock Interviews
A1: # | B1: Date | C1: Real or mock | D1: Round | E1: Level | F1: Question | G1: My answer (summary) | H1: Evaluation (1-5) | I1: Missed concepts | J1: Improved answer | K1: Follow-up revision task | L1: Revision done?
A2: 1 | B2: 46027 | C2: Mock | D2: Python & Django | E2: Beginner | F2: Explain mutable vs immutable (delete me) | G2: (your answer) | H2: 3 | I2: Default mutable args | J2: (improved answer) | K2: Redo Python Day 2 exercise 4 | L2: No
A3: 2
A4: 3
A5: 4
A6: 5
A7: 6
A8: 7
A9: 8
A10: 9
A11: 10
A12: 11
A13: 12
A14: 13
... A201: 200
A204: Do not look at answers before attempting. Record each question, your answer, honest evaluation, missed concepts, improved answer and a follow-up task. Row 2 is an example and not counted.

Sheet Projects & Review
A1: Portfolio projects and code review checklist
A2: Three projects, finished and deployed, beat many unfinished ones. Evidence column: repo link, test output, URL.
A3: ID | B3: Project | C3: Milestone | D3: Target day | E3: Acceptance criteria | F3: Status | G3: Evidence / link
A4: 1 | B4: Project 1: DRF Booking API | C4: M1 Models and schema | D4: 18 | E4: Users, resources, bookings with constraints; migrations apply | F4: Not Started
A5: 1 | B5: Project 1: DRF Booking API | C5: M2 CRUD API | D5: 18 | E5: Serializers + viewsets; validation errors correct | F5: Not Started
A6: 1 | B6: Project 1: DRF Booking API | C6: M3 JWT auth and role permissions | D6: 19 | E6: Admin/staff/customer roles enforced by tests | F6: Not Started
A7: 1 | B7: Project 1: DRF Booking API | C7: M4 Double-booking prevention | D7: 16 | E7: atomic + select_for_update; concurrency test proves it | F7: Not Started
A8: 1 | B8: Project 1: DRF Booking API | C8: M5 Tests, N+1 fixes, OpenAPI, README | D8: 20 | E8: Critical paths tested; query counts documented; README runs from scratch | F8: Not Started
A9: 1 | B9: Project 1: DRF Booking API | C9: M6 Celery reminders | D9: 27 | E9: Retries and idempotency key tested | F9: Not Started
A10: A | B10: Project A: FastAPI Task API | C10: M1 Skeleton and schemas | D10: 22 | E10: CRUD routes documented in /docs | F10: Not Started
A11: A | B11: Project A: FastAPI Task API | C11: M2 Auth and roles via dependencies | D11: 23 | E11: JWT + role tests | F11: Not Started
A12: A | B12: Project A: FastAPI Task API | C12: M3 PostgreSQL, Alembic, pagination, filtering | D12: 24 | E12: Migrations clean; pagination tested | F12: Not Started
A13: A | B13: Project A: FastAPI Task API | C13: M4 Tests and Docker | D13: 25 | E13: pytest passes; container runs | F13: Not Started
A14: A | B14: Project A: FastAPI Task API | C14: M5 Redis cache and rate limit | D14: 26 | E14: Cache hits visible; limiter tested | F14: Not Started
A15: B | B15: Project B: Advanced async service | C15: M1 External API client (async, timeout, retry) | D15: 29 | E15: Failures handled; tested with mocks | F15: Not Started
... A23: D | B23: Deployment (one project) | C23: D5 Health checks, logging, docs | D23: 50 | E23: /health, /ready; README + ADRs | F23: Not Started
A26: # | B26: Review area | C26: Checklist item | F26: Done?
A27: 1 | B27: Correctness | C27: Handles edge cases and invalid input
A28: 2 | B28: Correctness | C28: Concurrency and transactions considered
A29: 3 | B29: Readability | C29: Clear names, small functions, no dead code
A30: 4 | B30: Readability | C30: Comments explain why, not what
A31: 5 | B31: Maintainability | C31: Layered structure; config separated from code
A32: 6 | B32: Maintainability | C32: No duplicated logic; migrations reviewed
A33: 7 | B33: Testing | C33: Critical paths and failure cases have tests
A34: 8 | B34: Testing | C34: Tests are independent and repeatable
A35: 9 | B35: Security | C35: No secrets in repo; input validated; auth on every route
A36: 10 | B36: Security | C36: SQL injection, CSRF/CORS considered
A37: 11 | B37: Performance | C37: No N+1 queries; indexes for hot queries
A38: 12 | B38: Performance | C38: Timeouts and caching considered

Sheet Weak Areas
A1: # | B1: Date found | C1: Subject | D1: Topic / weakness | E1: Found by | F1: Severity | G1: Remediation task | H1: Target date | I1: Status | J1: Retest result
A2: 1
A3: 2
A4: 3
A5: 4
A6: 5
A7: 6
A8: 7
A9: 8
A10: 9
A11: 10
A12: 11
A13: 12
... A101: 100

Sheet Weekly Review
A1: Week | B1: Starts | C1: Ends | D1: Plan days done | E1: Plan days in week | F1: Avg confidence | G1: Weekly test score % | H1: Applications | I1: Outreach messages | J1: DSA problems logged | K1: Mock interviews | L1: Biggest win | M1: Biggest gap | N1: What I change next week
A2: 1 | B2: ='Learning Dashboard'!$B$3+0 -> 46311 | C2: ='Learning Dashboard'!$B$3+6 -> 46317 | D2: =COUNTIFS('60-Day Plan'!$A$2:$A$61,">=1",'60-Day Plan'!$A$2:$A$61,"<=7",'60-Day Plan'!$N$2:$N$61,"Completed") -> 0 | E2: 7 | F2: =IFERROR(AVERAGEIFS('60-Day Plan'!$O$2:$O$61,'60-Day Plan'!$A$2:$A$61,">=1",'60-Day Plan'!$A$2:$A$61,"<=7"),"") | H2: =COUNTIFS(Applications!$B$3:$B$300,">="&B2,Applications!$B$3:$B$300,"<="&C2) -> 0 | I2: =COUNTIFS(Outreach!$B$3:$B$300,">="&B2,Outreach!$B$3:$B$300,"<="&C2) -> 0 | J2: =COUNTIFS('DSA Log'!$B$3:$B$201,">="&B2,'DSA Log'!$B$3:$B$201,"<="&C2) -> 0 | K2: =COUNTIFS('Mock Interviews'!$B$3:$B$201,">="&B2,'Mock Interviews'!$B$3:$B$201,"<="&C2) -> 0
A3: 2 | B3: ='Learning Dashboard'!$B$3+7 -> 46318 | C3: ='Learning Dashboard'!$B$3+13 -> 46324 | D3: =COUNTIFS('60-Day Plan'!$A$2:$A$61,">=8",'60-Day Plan'!$A$2:$A$61,"<=14",'60-Day Plan'!$N$2:$N$61,"Completed") -> 0 | E3: 7 | F3: =IFERROR(AVERAGEIFS('60-Day Plan'!$O$2:$O$61,'60-Day Plan'!$A$2:$A$61,">=8",'60-Day Plan'!$A$2:$A$61,"<=14"),"") | H3: =COUNTIFS(Applications!$B$3:$B$300,">="&B3,Applications!$B$3:$B$300,"<="&C3) -> 0 | I3: =COUNTIFS(Outreach!$B$3:$B$300,">="&B3,Outreach!$B$3:$B$300,"<="&C3) -> 0 | J3: =COUNTIFS('DSA Log'!$B$3:$B$201,">="&B3,'DSA Log'!$B$3:$B$201,"<="&C3) -> 0 | K3: =COUNTIFS('Mock Interviews'!$B$3:$B$201,">="&B3,'Mock Interviews'!$B$3:$B$201,"<="&C3) -> 0
A4: 3 | B4: ='Learning Dashboard'!$B$3+14 -> 46325 | C4: ='Learning Dashboard'!$B$3+20 -> 46331 | D4: =COUNTIFS('60-Day Plan'!$A$2:$A$61,">=15",'60-Day Plan'!$A$2:$A$61,"<=21",'60-Day Plan'!$N$2:$N$61,"Completed") -> 0 | E4: 7 | F4: =IFERROR(AVERAGEIFS('60-Day Plan'!$O$2:$O$61,'60-Day Plan'!$A$2:$A$61,">=15",'60-Day Plan'!$A$2:$A$61,"<=21"),"") | H4: =COUNTIFS(Applications!$B$3:$B$300,">="&B4,Applications!$B$3:$B$300,"<="&C4) -> 0 | I4: =COUNTIFS(Outreach!$B$3:$B$300,">="&B4,Outreach!$B$3:$B$300,"<="&C4) -> 0 | J4: =COUNTIFS('DSA Log'!$B$3:$B$201,">="&B4,'DSA Log'!$B$3:$B$201,"<="&C4) -> 0 | K4: =COUNTIFS('Mock Interviews'!$B$3:$B$201,">="&B4,'Mock Interviews'!$B$3:$B$201,"<="&C4) -> 0
A5: 4 | B5: ='Learning Dashboard'!$B$3+21 -> 46332 | C5: ='Learning Dashboard'!$B$3+27 -> 46338 | D5: =COUNTIFS('60-Day Plan'!$A$2:$A$61,">=22",'60-Day Plan'!$A$2:$A$61,"<=28",'60-Day Plan'!$N$2:$N$61,"Completed") -> 0 | E5: 7 | F5: =IFERROR(AVERAGEIFS('60-Day Plan'!$O$2:$O$61,'60-Day Plan'!$A$2:$A$61,">=22",'60-Day Plan'!$A$2:$A$61,"<=28"),"") | H5: =COUNTIFS(Applications!$B$3:$B$300,">="&B5,Applications!$B$3:$B$300,"<="&C5) -> 0 | I5: =COUNTIFS(Outreach!$B$3:$B$300,">="&B5,Outreach!$B$3:$B$300,"<="&C5) -> 0 | J5: =COUNTIFS('DSA Log'!$B$3:$B$201,">="&B5,'DSA Log'!$B$3:$B$201,"<="&C5) -> 0 | K5: =COUNTIFS('Mock Interviews'!$B$3:$B$201,">="&B5,'Mock Interviews'!$B$3:$B$201,"<="&C5) -> 0
A6: 5 | B6: ='Learning Dashboard'!$B$3+28 -> 46339 | C6: ='Learning Dashboard'!$B$3+34 -> 46345 | D6: =COUNTIFS('60-Day Plan'!$A$2:$A$61,">=29",'60-Day Plan'!$A$2:$A$61,"<=35",'60-Day Plan'!$N$2:$N$61,"Completed") -> 0 | E6: 7 | F6: =IFERROR(AVERAGEIFS('60-Day Plan'!$O$2:$O$61,'60-Day Plan'!$A$2:$A$61,">=29",'60-Day Plan'!$A$2:$A$61,"<=35"),"") | H6: =COUNTIFS(Applications!$B$3:$B$300,">="&B6,Applications!$B$3:$B$300,"<="&C6) -> 0 | I6: =COUNTIFS(Outreach!$B$3:$B$300,">="&B6,Outreach!$B$3:$B$300,"<="&C6) -> 0 | J6: =COUNTIFS('DSA Log'!$B$3:$B$201,">="&B6,'DSA Log'!$B$3:$B$201,"<="&C6) -> 0 | K6: =COUNTIFS('Mock Interviews'!$B$3:$B$201,">="&B6,'Mock Interviews'!$B$3:$B$201,"<="&C6) -> 0
A7: 6 | B7: ='Learning Dashboard'!$B$3+35 -> 46346 | C7: ='Learning Dashboard'!$B$3+41 -> 46352 | D7: =COUNTIFS('60-Day Plan'!$A$2:$A$61,">=36",'60-Day Plan'!$A$2:$A$61,"<=42",'60-Day Plan'!$N$2:$N$61,"Completed") -> 0 | E7: 7 | F7: =IFERROR(AVERAGEIFS('60-Day Plan'!$O$2:$O$61,'60-Day Plan'!$A$2:$A$61,">=36",'60-Day Plan'!$A$2:$A$61,"<=42"),"") | H7: =COUNTIFS(Applications!$B$3:$B$300,">="&B7,Applications!$B$3:$B$300,"<="&C7) -> 0 | I7: =COUNTIFS(Outreach!$B$3:$B$300,">="&B7,Outreach!$B$3:$B$300,"<="&C7) -> 0 | J7: =COUNTIFS('DSA Log'!$B$3:$B$201,">="&B7,'DSA Log'!$B$3:$B$201,"<="&C7) -> 0 | K7: =COUNTIFS('Mock Interviews'!$B$3:$B$201,">="&B7,'Mock Interviews'!$B$3:$B$201,"<="&C7) -> 0
A8: 7 | B8: ='Learning Dashboard'!$B$3+42 -> 46353 | C8: ='Learning Dashboard'!$B$3+48 -> 46359 | D8: =COUNTIFS('60-Day Plan'!$A$2:$A$61,">=43",'60-Day Plan'!$A$2:$A$61,"<=49",'60-Day Plan'!$N$2:$N$61,"Completed") -> 0 | E8: 7 | F8: =IFERROR(AVERAGEIFS('60-Day Plan'!$O$2:$O$61,'60-Day Plan'!$A$2:$A$61,">=43",'60-Day Plan'!$A$2:$A$61,"<=49"),"") | H8: =COUNTIFS(Applications!$B$3:$B$300,">="&B8,Applications!$B$3:$B$300,"<="&C8) -> 0 | I8: =COUNTIFS(Outreach!$B$3:$B$300,">="&B8,Outreach!$B$3:$B$300,"<="&C8) -> 0 | J8: =COUNTIFS('DSA Log'!$B$3:$B$201,">="&B8,'DSA Log'!$B$3:$B$201,"<="&C8) -> 0 | K8: =COUNTIFS('Mock Interviews'!$B$3:$B$201,">="&B8,'Mock Interviews'!$B$3:$B$201,"<="&C8) -> 0
A9: 8 | B9: ='Learning Dashboard'!$B$3+49 -> 46360 | C9: ='Learning Dashboard'!$B$3+55 -> 46366 | D9: =COUNTIFS('60-Day Plan'!$A$2:$A$61,">=50",'60-Day Plan'!$A$2:$A$61,"<=56",'60-Day Plan'!$N$2:$N$61,"Completed") -> 0 | E9: 7 | F9: =IFERROR(AVERAGEIFS('60-Day Plan'!$O$2:$O$61,'60-Day Plan'!$A$2:$A$61,">=50",'60-Day Plan'!$A$2:$A$61,"<=56"),"") | H9: =COUNTIFS(Applications!$B$3:$B$300,">="&B9,Applications!$B$3:$B$300,"<="&C9) -> 0 | I9: =COUNTIFS(Outreach!$B$3:$B$300,">="&B9,Outreach!$B$3:$B$300,"<="&C9) -> 0 | J9: =COUNTIFS('DSA Log'!$B$3:$B$201,">="&B9,'DSA Log'!$B$3:$B$201,"<="&C9) -> 0 | K9: =COUNTIFS('Mock Interviews'!$B$3:$B$201,">="&B9,'Mock Interviews'!$B$3:$B$201,"<="&C9) -> 0
A10: 9 | B10: ='Learning Dashboard'!$B$3+56 -> 46367 | C10: ='Learning Dashboard'!$B$3+59 -> 46370 | D10: =COUNTIFS('60-Day Plan'!$A$2:$A$61,">=57",'60-Day Plan'!$A$2:$A$61,"<=60",'60-Day Plan'!$N$2:$N$61,"Completed") -> 0 | E10: 4 | F10: =IFERROR(AVERAGEIFS('60-Day Plan'!$O$2:$O$61,'60-Day Plan'!$A$2:$A$61,">=57",'60-Day Plan'!$A$2:$A$61,"<=60"),"") | H10: =COUNTIFS(Applications!$B$3:$B$300,">="&B10,Applications!$B$3:$B$300,"<="&C10) -> 0 | I10: =COUNTIFS(Outreach!$B$3:$B$300,">="&B10,Outreach!$B$3:$B$300,"<="&C10) -> 0 | J10: =COUNTIFS('DSA Log'!$B$3:$B$201,">="&B10,'DSA Log'!$B$3:$B$201,"<="&C10) -> 0 | K10: =COUNTIFS('Mock Interviews'!$B$3:$B$201,">="&B10,'Mock Interviews'!$B$3:$B$201,"<="&C10) -> 0
A12: Weekly review (15 min, every Review day): 1) What did I actually learn, with evidence? 2) Which topics did I avoid? 3) What failed in the tests? 4) What do I drop or add? 5) Should I accept interviews now? (see Dashboard checkpoint).
A13: Week 9 covers days 57-60 (4 days). Job metrics count entries dated within each learning week.

Sheet 7-Day Plan
A1: Day | B1: Date | C1: Task | D1: Target | E1: Done? | F1: Notes
A2: 1 | B2: ='Start Here'!$B$3+A2-1 -> 46309 | C2: Update CV: outcomes first, Django/DRF/PostgreSQL/Redis/Celery/Docker at top | D2: 1 CV
A3: 1 | B3: ='Start Here'!$B$3+A3-1 -> 46309 | C3: Update LinkedIn headline, About and Experience | D3: 1 profile
A4: 1 | B4: ='Start Here'!$B$3+A4-1 -> 46309 | C4: Build target list (ex-colleagues, agencies, Gulf recruiters, others) | D4: 40 names
A5: 1 | B5: ='Start Here'!$B$3+A5-1 -> 46309 | C5: Message Wasif: ask who needs a Django developer | D5: 1 message
A6: 2 | B6: ='Start Here'!$B$3+A6-1 -> 46310 | C6: Send brother a specific intro request (3-5 hiring contacts / vendors) | D6: 1 message
A7: 2 | B7: ='Start Here'!$B$3+A7-1 -> 46310 | C7: Send outreach messages | D7: 10 sent
A8: 3 | B8: ='Start Here'!$B$3+A8-1 -> 46311 | C8: Send outreach messages | D8: 10 sent
A9: 3 | B9: ='Start Here'!$B$3+A9-1 -> 46311 | C9: Apply to well-matched jobs | D9: 3-5 applications
A10: 4 | B10: ='Start Here'!$B$3+A10-1 -> 46312 | C10: Follow up on unanswered messages | D10: all open
